Workbook
Name FileName: NOTES!$B$8

Sheet NOTES
A1: AZ Create SampSummary Table
A2: Specific Task
A4: Erik.Leppo@tetratech.com
A5: 43262
A7: Path & FileName | B7: =LEFT(CELL("filename",B7),FIND("]",CELL("filename",B7))) -> P:\Current\OtherGov\City of San Diego\FY2018\pkg data\[SampSummary_Erik.xlsx]
A8: FileName: | B8: =MID(CELL("filename",B8),FIND("[",CELL("filename",B8)),(FIND("]",CELL("filename",B8))-FIND("[",CELL("filename",B8)))+1) -> [SampSummary_Erik.xlsx]
A9: TabName: | B9: =MID(CELL("filename",B9),FIND("]",CELL("filename",B9))+1,LEN(CELL("filename",B9))-FIND("]",CELL("filename",B9))) -> NOTES
A11: Description of Work
A12: Needed for CASTfxn R package.
A15: Worksheet | B15: Descriptions | C15: Link
A16: NOTES | B16: Description of work and other worksheets. | C16: =HYPERLINK(FileName&A16&"!A1",A16) -> NOTES
A17: Sheet2 | C17: =HYPERLINK(FileName&A17&"!A1",A17) -> Sheet2
A18: Sheet3 | C18: =HYPERLINK(FileName&A18&"!A1",A18) -> Sheet3

Sheet data.SampSummary
A1: StationID_Master | B1: CollDate | C1: Station_Date | D1: ChemSampleID | E1: PhabSampID | F1: BMI.Metrics.SampID | G1: Algae.Metrics.SampID
A2: LCWLR001.23 | B2: 33792 | C2: LCWLR001.23_33792 | E2: 148_1 | F2: 2346_1 | G2: LCWLR001.23_33792
A3: SRTON062.28 | B3: 42131 | C3: SRTON062.28_42131 | D3: SRTON062.28_42131 | E3: 1388_1 | F3: 3947_1 | G3: SRTON062.28_42131
A4: SPGRA007.71 | B4: 34060 | C4: SPGRA007.71_34060 | E4: 315_1 | F4: 2507_1 | G4: SPGRA007.71_34060
A5: LCCOL003.03 | B5: 41780 | C5: LCCOL003.03_41780 | D5: LCCOL003.03_41780 | E5: 1361_1 | F5: 3901_1 | G5: LCCOL003.03_41780
A6: VROAK048.36 | B6: 39637 | C6: VROAK048.36_39637 | E6: 967_1 | F6: 3642_1 | G6: VROAK048.36_39637
A7: LCWLR005.31 | B7: 33792 | C7: LCWLR005.31_33792 | E7: 149_1 | F7: 2347_1 | G7: LCWLR005.31_33792
A8: SPRMC011.48 | B8: 34430 | C8: SPRMC011.48_34430 | E8: 364_1 | F8: 2258_1 | G8: SPRMC011.48_34430
A9: VROAK049.65 | B9: 38133 | C9: VROAK049.65_38133 | E9: 834_1 | F9: 3432_1 | G9: VROAK049.65_38133
A10: VRWCL023.36 | B10: 34841 | C10: VRWCL023.36_34841 | F10: 2616_1 | G10: VRWCL023.36_34841
A11: LCMLK001.18 | B11: 39224 | C11: LCMLK001.18_39224 | D11: LCMLK001.18_39224 | E11: 916_1 | F11: 3388_1 | G11: LCMLK001.18_39224
A12: VRPIE016.49 | B12: 40708 | C12: VRPIE016.49_40708 | D12: VRPIE016.49_40708 | E12: 1218_1 | F12: 3818_1 | G12: VRPIE016.49_40708
A13: VROAK047.96 | B13: 35922 | C13: VROAK047.96_35922 | E13: 555_1 | F13: 2725_1 | G13: VROAK047.96_35922
A14: UGBLR030.24 | B14: 41828 | C14: UGBLR030.24_41828 | D14: UGBLR030.24_41828 | E14: 1373_1 | F14: 3928_1 | G14: UGBLR030.24_41828
A15: UGSFR144.95 | B15: 36654 | C15: UGSFR144.95_36654 | F15: 2884_1 | G15: UGSFR144.95_36654
A16: VRPIE016.49 | B16: 35571 | C16: VRPIE016.49_35571 | E16: 520_1 | F16: 2684_1 | G16: VRPIE016.49_35571
A17: LCNUT025.35 | B17: 41779 | C17: LCNUT025.35_41779 | E17: 1362_1 | F17: 3908_1 | G17: LCNUT025.35_41779
A18: SRUDC000.02 | B18: 42543 | C18: SRUDC000.02_42543 | D18: SRUDC000.02_42543 | E18: 1435_1 | F18: 3982_1 | G18: SRUDC000.02_42543
A19: SRBGY002.86 | B19: 41801 | C19: SRBGY002.86_41801 | D19: SRBGY002.86_41801 | E19: 1366_1 | F19: 3918_1 | G19: SRBGY002.86_41801
A20: LCMIN018.05 | B20: 34505 | C20: LCMIN018.05_34505 | E20: 342_1 | F20: 2537_1 | G20: LCMIN018.05_34505
A21: LCELR005.67 | B21: 41758 | C21: LCELR005.67_41758 | D21: LCELR005.67_41758 | E21: 1369_1 | F21: 3903_1 | G21: LCELR005.67_41758
A22: UGCMB004.23 | B22: 35206 | C22: UGCMB004.23_35206 | E22: 494_1 | F22: 3011_1 | G22: UGCMB004.23_35206
A23: SRFIS010.92 | B23: 42541 | C23: SRFIS010.92_42541 | D23: SRFIS010.92_42541 | E23: 1436_1 | F23: 3975_2 | G23: SRFIS010.92_42541
A24: VRWOK000.82 | B24: 38134 | C24: VRWOK000.82_38134 | E24: 835_1 | F24: 3442_1 | G24: VRWOK000.82_38134
A25: UGBLR046.35 | B25: 34506 | C25: UGBLR046.35_34506 | E25: 382_1 | F25: 2279_1 | G25: UGBLR046.35_34506
A26: UGFRY009.52 | B26: 34479 | C26: UGFRY009.52_34479 | E26: 389_1 | F26: 2286_1 | G26: UGFRY009.52_34479
A27: VRWOK000.82 | B27: 39609 | C27: VRWOK000.82_39609 | D27: VRWOK000.82_39609 | E27: 978_1 | F27: 3653_1 | G27: VRWOK000.82_39609
A28: VRWEB009.13 | B28: 34493 | C28: VRWEB009.13_34493 | E28: 402_1 | F28: 2547_1 | G28: VRWEB009.13_34493
A29: SPRUC007.81 | B29: 38519 | C29: SPRUC007.81_38519 | E29: 870_1 | F29: 3467_1 | G29: SPRUC007.81_38519
A30: UGLAN000.60 | B30: 40023 | C30: UGLAN000.60_40023 | D30: UGLAN000.60_40023 | F30: 3738_1 | G30: UGLAN000.60_40023
A31: SRCYN045.73 | B31: 34485 | C31: SRCYN045.73_34485 | E31: 369_1 | F31: 2263_1 | G31: SRCYN045.73_34485
A32: UGMRW011.38 | B32: 33715 | C32: UGMRW011.38_33715 | E32: 200_1 | F32: 2399_1 | G32: UGMRW011.38_33715
A33: SRREY001.14 | B33: 33735 | C33: SRREY001.14_33735 | E33: 184_1 | F33: 2383_1 | G33: SRREY001.14_33735
A34: UGBLR046.35 | B34: 40023 | C34: UGBLR046.35_40023 | D34: UGBLR046.35_40023 | E34: 1100_1 | F34: 3728_1 | G34: UGBLR046.35_40023
A35: SREFB000.91 | B35: 37425 | C35: SREFB000.91_37425 | E35: 679_1 | F35: 3107_1 | G35: SREFB000.91_37425
A36: UGCMB004.23 | B36: 41443 | C36: UGCMB004.23_41443 | D36: UGCMB004.23_41443 | E36: 1325_1 | F36: 3879_2 | G36: UGCMB004.23_41443
A37: SPWRC000.48 | B37: 34428 | C37: SPWRC000.48_34428 | E37: 405_1 | F37: 2550_1 | G37: SPWRC000.48_34428
A38: CGNCA028.70 | B38: 34493 | C38: CGNCA028.70_34493 | E38: 330_1 | F38: 2523_1 | G38: CGNCA028.70_34493
A39: VRWCL036.37 | B39: 34841 | C39: VRWCL036.37_34841 | F39: 2617_1 | G39: VRWCL036.37_34841
A40: UGMRW011.38 | B40: 34480 | C40: UGMRW011.38_34480 | E40: 392_1 | F40: 2289_1 | G40: UGMRW011.38_34480
...

Sheet chem
A1: SITE_ID | B1: SampDate | C1: ChemSamp | D1: count
A2: LCSIL006.13 | B2: 39036 | C2: =A2&"_"&B2 -> LCSIL006.13_39036 | D2: =COUNTIF(data.SampSummary!$C$2:$C$1407,C2) -> 0
A3: LCSLR001.42 | B3: 39037 | C3: =A3&"_"&B3 -> LCSLR001.42_39037 | D3: =COUNTIF(data.SampSummary!$C$2:$C$1407,C3) -> 0
A4: LCLCR216.67 | B4: 39049 | C4: =A4&"_"&B4 -> LCLCR216.67_39049 | D4: =COUNTIF(data.SampSummary!$C$2:$C$1407,C4) -> 0
A5: LCLCR226.31 | B5: 39049 | C5: =A5&"_"&B5 -> LCLCR226.31_39049 | D5: =COUNTIF(data.SampSummary!$C$2:$C$1407,C5) -> 0
A6: LCLCR211.73 | B6: 39049 | C6: =A6&"_"&B6 -> LCLCR211.73_39049 | D6: =COUNTIF(data.SampSummary!$C$2:$C$1407,C6) -> 0
A7: LCLCR311.31 | B7: 39049 | C7: =A7&"_"&B7 -> LCLCR311.31_39049 | D7: =COUNTIF(data.SampSummary!$C$2:$C$1407,C7) -> 0
A8: LCCOY000.71 | B8: 39049 | C8: =A8&"_"&B8 -> LCCOY000.71_39049 | D8: =COUNTIF(data.SampSummary!$C$2:$C$1407,C8) -> 0
A9: LCSIL006.13 | B9: 39147 | C9: =A9&"_"&B9 -> LCSIL006.13_39147 | D9: =COUNTIF(data.SampSummary!$C$2:$C$1407,C9) -> 0
A10: LCLCR226.31 | B10: 39147 | C10: =A10&"_"&B10 -> LCLCR226.31_39147 | D10: =COUNTIF(data.SampSummary!$C$2:$C$1407,C10) -> 0
A11: LCLCR216.67 | B11: 39147 | C11: =A11&"_"&B11 -> LCLCR216.67_39147 | D11: =COUNTIF(data.SampSummary!$C$2:$C$1407,C11) -> 0
A12: LCLCR211.73 | B12: 39147 | C12: =A12&"_"&B12 -> LCLCR211.73_39147 | D12: =COUNTIF(data.SampSummary!$C$2:$C$1407,C12) -> 0
A13: LCCOY000.71 | B13: 39148 | C13: =A13&"_"&B13 -> LCCOY000.71_39148 | D13: =COUNTIF(data.SampSummary!$C$2:$C$1407,C13) -> 0
... A2543: LCWAN000.56 | B2543: 39644 | C2543: =A2543&"_"&B2543 -> LCWAN000.56_39644 | D2543: =COUNTIF(data.SampSummary!$C$2:$C$1407,C2543) -> 0

Sheet Habitat
A1: StationID | B1: CollDate | C1: =A1&"_"&B1 -> StationID_CollDate | D1: SampID | E1: MatchMaster
A2: CGNAN000.20 | B2: 38909 | C2: =A2&"_"&B2 -> CGNAN000.20_38909 | D2: 888_1 | E2: =COUNTIF(data.SampSummary!$C$2:$C$958,C2) -> 1
A3: VRVER164.63 | B3: 37047 | C3: =A3&"_"&B3 -> VRVER164.63_37047 | D3: 609_1 | E3: =COUNTIF(data.SampSummary!$C$2:$C$958,C3) -> 1
A4: SPTUR028.53 | B4: 41043 | C4: =A4&"_"&B4 -> SPTUR028.53_41043 | D4: 1262_1 | E4: =COUNTIF(data.SampSummary!$C$2:$C$958,C4) -> 1
A5: UGEAG040.33 | B5: 38854 | C5: =A5&"_"&B5 -> UGEAG040.33_38854 | D5: 880_1 | E5: =COUNTIF(data.SampSummary!$C$2:$C$958,C5) -> 1
A6: LCRUD003.45 | B6: 39225 | C6: =A6&"_"&B6 -> LCRUD003.45_39225 | D6: 917_1 | E6: =COUNTIF(data.SampSummary!$C$2:$C$958,C6) -> 1
A7: UGSFR034.57 | B7: 41416 | C7: =A7&"_"&B7 -> UGSFR034.57_41416 | D7: 1324_1 | E7: =COUNTIF(data.SampSummary!$C$2:$C$958,C7) -> 1
A8: LCSHL031.05 | B8: 41771 | C8: =A8&"_"&B8 -> LCSHL031.05_41771 | D8: 1352_1 | E8: =COUNTIF(data.SampSummary!$C$2:$C$958,C8) -> 1
A9: SRTON019.37 | B9: 36628 | C9: =A9&"_"&B9 -> SRTON019.37_36628 | D9: 793_1 | E9: =COUNTIF(data.SampSummary!$C$2:$C$958,C9) -> 2
A10: SRWRK007.97 | B10: 39615 | C10: =A10&"_"&B10 -> SRWRK007.97_39615 | D10: 1002_1 | E10: =COUNTIF(data.SampSummary!$C$2:$C$958,C10) -> 1
A11: SRHAG013.09 | B11: 41745 | C11: =A11&"_"&B11 -> SRHAG013.09_41745 | D11: 1340_1 | E11: =COUNTIF(data.SampSummary!$C$2:$C$958,C11) -> 1
A12: VRWCL011.16 | B12: 36283 | C12: =A12&"_"&B12 -> VRWCL011.16_36283 | D12: 570_1 | E12: =COUNTIF(data.SampSummary!$C$2:$C$958,C12) -> 1
A13: VREVR034.80 | B13: 37732 | C13: =A13&"_"&B13 -> VREVR034.80_37732 | D13: 701_1 | E13: =COUNTIF(data.SampSummary!$C$2:$C$958,C13) -> 1
... A1318: VRVER107.68 | B1318: 36283 | C1318: =A1318&"_"&B1318 -> VRVER107.68_36283 | D1318: 1230_1 | E1318: =COUNTIF(data.SampSummary!$C$2:$C$958,C1318) -> 0
